INFO:     Started server process [5168]
INFO:     Waiting for application startup.
(trapped) error reading bcrypt version
Traceback (most recent call last):
  File "/home/runner/workspace/.pythonlibs/lib/python3.11/site-packages/passlib/handlers/bcrypt.py", line 620, in _load_backend_mixin
    version = _bcrypt.__about__.__version__
              ^^^^^^^^^^^^^^^^^
AttributeError: module 'bcrypt' has no attribute '__about__'
ERROR:    Traceback (most recent call last):
  File "/home/runner/workspace/.pythonlibs/lib/python3.11/site-packages/sqlalchemy/engine/base.py", line 2114, in _exec_insertmany_context
    dialect.do_execute(
  File "/home/runner/workspace/.pythonlibs/lib/python3.11/site-packages/sqlalchemy/engine/default.py", line 943, in do_execute
    cursor.execute(statement, parameters)
psycopg2.errors.UndefinedColumn: column "ativo" of relation "operadoras" does not exist
LINE 1: INSERT INTO operadoras (nome, ativo, url_portal, created_at)...
                                      ^


The above exception was the direct cause of the following exception:

Traceback (most recent call last):
  File "/home/runner/workspace/.pythonlibs/lib/python3.11/site-packages/starlette/routing.py", line 692, in lifespan
    async with self.lifespan_context(app) as maybe_state:
  File "/nix/store/clx0mcir7qw8zk36zbr4jra789g3knf6-python3-3.11.10/lib/python3.11/contextlib.py", line 210, in __aenter__
    return await anext(self.gen)
           ^^^^^^^^^^^^^^^^^^^^^
  File "/home/runner/workspace/app.py", line 75, in lifespan
    await initialize_system_data(db)
  File "/home/runner/workspace/app.py", line 135, in initialize_system_data
    db.flush()  # Para obter os IDs
    ^^^^^^^^^^
  File "/home/runner/workspace/.pythonlibs/lib/python3.11/site-packages/sqlalchemy/orm/session.py", line 4345, in flush
    self._flush(objects)
  File "/home/runner/workspace/.pythonlibs/lib/python3.11/site-packages/sqlalchemy/orm/session.py", line 4480, in _flush
    with util.safe_reraise():
  File "/home/runner/workspace/.pythonlibs/lib/python3.11/site-packages/sqlalchemy/util/langhelpers.py", line 224, in __exit__
    raise exc_value.with_traceback(exc_tb)
  File "/home/runner/workspace/.pythonlibs/lib/python3.11/site-packages/sqlalchemy/orm/session.py", line 4441, in _flush
    flush_context.execute()
  File "/home/runner/workspace/.pythonlibs/lib/python3.11/site-packages/sqlalchemy/orm/unitofwork.py", line 466, in execute
    rec.execute(self)
  File "/home/runner/workspace/.pythonlibs/lib/python3.11/site-packages/sqlalchemy/orm/unitofwork.py", line 642, in execute
    util.preloaded.orm_persistence.save_obj(
  File "/home/runner/workspace/.pythonlibs/lib/python3.11/site-packages/sqlalchemy/orm/persistence.py", line 93, in save_obj
    _emit_insert_statements(
  File "/home/runner/workspace/.pythonlibs/lib/python3.11/site-packages/sqlalchemy/orm/persistence.py", line 1143, in _emit_insert_statements
    result = connection.execute(
             ^^^^^^^^^^^^^^^^^^^
  File "/home/runner/workspace/.pythonlibs/lib/python3.11/site-packages/sqlalchemy/engine/base.py", line 1415, in execute
    return meth(
           ^^^^^
  File "/home/runner/workspace/.pythonlibs/lib/python3.11/site-packages/sqlalchemy/sql/elements.py", line 523, in _execute_on_connection
    return connection._execute_clauseelement(
           ^^^^^^^^^^^^^^^^^^^^^^^^^^^^^^^^^^
  File "/home/runner/workspace/.pythonlibs/lib/python3.11/site-packages/sqlalchemy/engine/base.py", line 1637, in _execute_clauseelement
    ret = self._execute_context(
          ^^^^^^^^^^^^^^^^^^^^^^
  File "/home/runner/workspace/.pythonlibs/lib/python3.11/site-packages/sqlalchemy/engine/base.py", line 1840, in _execute_context
    return self._exec_insertmany_context(dialect, context)
           ^^^^^^^^^^^^^^^^^^^^^^^^^^^^^^^^^^^^^^^^^^^^^^^
  File "/home/runner/workspace/.pythonlibs/lib/python3.11/site-packages/sqlalchemy/engine/base.py", line 2122, in _exec_insertmany_context
    self._handle_dbapi_exception(
  File "/home/runner/workspace/.pythonlibs/lib/python3.11/site-packages/sqlalchemy/engine/base.py", line 2351, in _handle_dbapi_exception
    raise sqlalchemy_exception.with_traceback(exc_info[2]) from e
  File "/home/runner/workspace/.pythonlibs/lib/python3.11/site-packages/sqlalchemy/engine/base.py", line 2114, in _exec_insertmany_context
    dialect.do_execute(
  File "/home/runner/workspace/.pythonlibs/lib/python3.11/site-packages/sqlalchemy/engine/default.py", line 943, in do_execute
    cursor.execute(statement, parameters)
sqlalchemy.exc.ProgrammingError: (psycopg2.errors.UndefinedColumn) column "ativo" of relation "operadoras" does not exist
LINE 1: INSERT INTO operadoras (nome, ativo, url_portal, created_at)...
                                      ^

[SQL: INSERT INTO operadoras (nome, ativo, url_portal, created_at) SELECT p0::VARCHAR, p1::BOOLEAN, p2::VARCHAR, p3::TIMESTAMP WITHOUT TIME ZONE FROM (VALUES (%(nome__0)s, %(ativo__0)s, %(url_portal__0)s, now(), 0), (%(nome__1)s, %(ativo__1)s, %(url_portal ... 281 characters truncated ... counter) ORDER BY sen_counter RETURNING operadoras.id, operadoras.created_at, operadoras.id AS id__1]
[parameters: {'ativo__0': True, 'nome__0': 'Vivo', 'url_portal__0': 'https://empresas.vivo.com.br', 'ativo__1': True, 'nome__1': 'OI', 'url_portal__1': 'https://empresas.oi.com.br', 'ativo__2': True, 'nome__2': 'Embratel', 'url_portal__2': 'https://empresas.embratel.com.br', 'ativo__3': True, 'nome__3': 'SAT', 'url_portal__3': 'https://sat.com.br', 'ativo__4': True, 'nome__4': 'DigitalNet', 'url_portal__4': 'https://digitalnet.com.br', 'ativo__5': True, 'nome__5': 'Azuton', 'url_portal__5': 'https://azuton.com.br'}]
(Background on this error at: https://sqlalche.me/e/20/f405)

ERROR:    Application startup failed. Exiting.
Aviso: Alguns serviços RPA não puderam ser importados: No module named 'services'
Iniciando Sistema de Orquestração RPA...
Iniciando Sistema de Orquestração RPA...
